Workbook

Sheet Summary
A1: SPECTRA | Investor Forecast Summary
A2: Premium view of the live forecast: year milestones, cash need, breakeven, and chart-ready data.
A4: Metric | B4: Year 1 | C4: Year 2 | D4: Year 3
A5: Ending Subscribers | B5: ='Forecast'!N7 | C5: ='Forecast'!Z7 | D5: ='Forecast'!AL7
A6: New Subscribers | B6: =SUM('Forecast'!C5:'Forecast'!N5) | C6: =SUM('Forecast'!O5:'Forecast'!Z5) | D6: =SUM('Forecast'!AA5:'Forecast'!AL5)
A7: Ending MRR | B7: ='Forecast'!N11 | C7: ='Forecast'!Z11 | D7: ='Forecast'!AL11
A8: Ending ARR | B8: ='Forecast'!N12 | C8: ='Forecast'!Z12 | D8: ='Forecast'!AL12
A9: Total Revenue | B9: =SUM('Forecast'!C11:'Forecast'!N11) | C9: =SUM('Forecast'!O11:'Forecast'!Z11) | D9: =SUM('Forecast'!AA11:'Forecast'!AL11)
A10: Total Expenses | B10: =SUM('Forecast'!C35:'Forecast'!N35) | C10: =SUM('Forecast'!O35:'Forecast'!Z35) | D10: =SUM('Forecast'!AA35:'Forecast'!AL35)
A11: EBITDA | B11: =SUM('Forecast'!C36:'Forecast'!N36) | C11: =SUM('Forecast'!O36:'Forecast'!Z36) | D11: =SUM('Forecast'!AA36:'Forecast'!AL36)
A14: Breakeven Month | B14: =IFERROR(INDEX(Forecast!$C$1:$AL$1,XMATCH(TRUE,Forecast!$C$36:$AL$36>0)),"Not reached")
A15: Peak Cash Need | B15: =ABS(MIN(0,MIN(Forecast!$C$37:$AL$37)))
A18: Chart Data | B18: Use this block for ARR / MRR / Subscribers / EBITDA charts
A19: Month | B19: Subscribers | C19: MRR | D19: ARR | E19: EBITDA
A20: Jun 26 | B20: ='Forecast'!C7 | C20: ='Forecast'!C11 | D20: ='Forecast'!C12 | E20: ='Forecast'!C36
A21: Jul 26 | B21: ='Forecast'!D7 | C21: ='Forecast'!D11 | D21: ='Forecast'!D12 | E21: ='Forecast'!D36
A22: Aug 26 | B22: ='Forecast'!E7 | C22: ='Forecast'!E11 | D22: ='Forecast'!E12 | E22: ='Forecast'!E36
A23: Sep 26 | B23: ='Forecast'!F7 | C23: ='Forecast'!F11 | D23: ='Forecast'!F12 | E23: ='Forecast'!F36
A24: Oct 26 | B24: ='Forecast'!G7 | C24: ='Forecast'!G11 | D24: ='Forecast'!G12 | E24: ='Forecast'!G36
A25: Nov 26 | B25: ='Forecast'!H7 | C25: ='Forecast'!H11 | D25: ='Forecast'!H12 | E25: ='Forecast'!H36
A26: Dec 26 | B26: ='Forecast'!I7 | C26: ='Forecast'!I11 | D26: ='Forecast'!I12 | E26: ='Forecast'!I36
A27: Jan 27 | B27: ='Forecast'!J7 | C27: ='Forecast'!J11 | D27: ='Forecast'!J12 | E27: ='Forecast'!J36
A28: Feb 27 | B28: ='Forecast'!K7 | C28: ='Forecast'!K11 | D28: ='Forecast'!K12 | E28: ='Forecast'!K36
A29: Mar 27 | B29: ='Forecast'!L7 | C29: ='Forecast'!L11 | D29: ='Forecast'!L12 | E29: ='Forecast'!L36
A30: Apr 27 | B30: ='Forecast'!M7 | C30: ='Forecast'!M11 | D30: ='Forecast'!M12 | E30: ='Forecast'!M36
A31: May 27 | B31: ='Forecast'!N7 | C31: ='Forecast'!N11 | D31: ='Forecast'!N12 | E31: ='Forecast'!N36
A32: Jun 27 | B32: ='Forecast'!O7 | C32: ='Forecast'!O11 | D32: ='Forecast'!O12 | E32: ='Forecast'!O36
A33: Jul 27 | B33: ='Forecast'!P7 | C33: ='Forecast'!P11 | D33: ='Forecast'!P12 | E33: ='Forecast'!P36
A34: Aug 27 | B34: ='Forecast'!Q7 | C34: ='Forecast'!Q11 | D34: ='Forecast'!Q12 | E34: ='Forecast'!Q36
A35: Sep 27 | B35: ='Forecast'!R7 | C35: ='Forecast'!R11 | D35: ='Forecast'!R12 | E35: ='Forecast'!R36
A36: Oct 27 | B36: ='Forecast'!S7 | C36: ='Forecast'!S11 | D36: ='Forecast'!S12 | E36: ='Forecast'!S36
A37: Nov 27 | B37: ='Forecast'!T7 | C37: ='Forecast'!T11 | D37: ='Forecast'!T12 | E37: ='Forecast'!T36
A38: Dec 27 | B38: ='Forecast'!U7 | C38: ='Forecast'!U11 | D38: ='Forecast'!U12 | E38: ='Forecast'!U36
A39: Jan 28 | B39: ='Forecast'!V7 | C39: ='Forecast'!V11 | D39: ='Forecast'!V12 | E39: ='Forecast'!V36
A40: Feb 28 | B40: ='Forecast'!W7 | C40: ='Forecast'!W11 | D40: ='Forecast'!W12 | E40: ='Forecast'!W36
A41: Mar 28 | B41: ='Forecast'!X7 | C41: ='Forecast'!X11 | D41: ='Forecast'!X12 | E41: ='Forecast'!X36
A42: Apr 28 | B42: ='Forecast'!Y7 | C42: ='Forecast'!Y11 | D42: ='Forecast'!Y12 | E42: ='Forecast'!Y36
A43: May 28 | B43: ='Forecast'!Z7 | C43: ='Forecast'!Z11 | D43: ='Forecast'!Z12 | E43: ='Forecast'!Z36
A44: Jun 28 | B44: ='Forecast'!AA7 | C44: ='Forecast'!AA11 | D44: ='Forecast'!AA12 | E44: ='Forecast'!AA36
A45: Jul 28 | B45: ='Forecast'!AB7 | C45: ='Forecast'!AB11 | D45: ='Forecast'!AB12 | E45: ='Forecast'!AB36
...

Sheet Assumptions
A1: SPECTRA | Assumptions Control Panel
A2: Change the warm gold cells. The Forecast and Summary tabs update from this control sheet.
A3: Generated from | B3: https://salonos.ai/.netlify/functions/financial-forecast
A4: Updated at | B4: 2026-05-14T10:37:13.432Z
A6: Business Base
A7: Metric | B7: Value | C7: Notes
A8: Starting Subscribers | B8: 160 | C8: Editable input used by first forecast month.
A9: Current MRR | B9: 11000 | C9: Current monthly recurring revenue in USD.
A10: Starting ARPU | B10: =B9/B8 | C10: Formula: Current MRR / Starting Subscribers.
A11: Israeli Customers | B11: 70 | C11: Used by VAT Israel calculated row.
A12: VAT % | B12: 0.1 | C12: Stored as a real Excel percentage.
A13: Forecast Start Month | B13: Jun 26 | C13: First model month.
A14: Forecast Months | B14: 36 | C14: 36-month forecast horizon.
A18: Monthly Growth Assumptions | B18: CAC, ARPU, churn and campaign spend by month
A19: Month | B19: CAC | C19: ARPU | D19: Churn % | E19: Campaign Spend
A20: Jun 26 | B20: 400 | C20: 68.75 | D20: 0.005 | E20: 1500
A21: Jul 26 | B21: 400 | C21: 68.75 | D21: 0.005 | E21: 1500
A22: Aug 26 | B22: 400 | C22: 68.75 | D22: 0.005 | E22: 3000
A23: Sep 26 | B23: 400 | C23: 68.75 | D23: 0.005 | E23: 3000
A24: Oct 26 | B24: 400 | C24: 68.75 | D24: 0.005 | E24: 4500
A25: Nov 26 | B25: 400 | C25: 68.75 | D25: 0.005 | E25: 5000
A26: Dec 26 | B26: 400 | C26: 68.75 | D26: 0.005 | E26: 7000
A27: Jan 27 | B27: 400 | C27: 90 | D27: 0.005 | E27: 12000
A28: Feb 27 | B28: 400 | C28: 90 | D28: 0.005 | E28: 20000
A29: Mar 27 | B29: 400 | C29: 90 | D29: 0.005 | E29: 20000
A30: Apr 27 | B30: 400 | C30: 120 | D30: 0.005 | E30: 20000
A31: May 27 | B31: 400 | C31: 120 | D31: 0.005 | E31: 20000
... A55: May 29 | B55: 400 | C55: 280 | D55: 0.005 | E55: 90000
A59: Expense Assumptions | B59: Catalog of expense lines and how each line is calculated
A60: Line ID | B60: Category | C60: Expense Line | D60: Type | E60: Base / Unit | F60: Notes
A61: rnd.achela | B61: Research & Development | C61: Achela developer | D61: fixedUsd | E61: 9333 | F61: Fixed monthly USD amount.
A62: rnd.it | B62: Research & Development | C62: IT / servers | D62: fixedUsd | E62: 2000 | F62: Fixed monthly USD amount.
A63: rnd.ai | B63: Research & Development | C63: AI tools | D63: fixedUsd | E63: 2000 | F63: Fixed monthly USD amount.
A64: ms.campaigns | B64: Marketing & Sales | C64: Campaigns | D64: linkedCampaigns | E64: 0 | F64: Mirrors Monthly Growth Assumptions: Campaign Spend.
A65: ms.campaignMgr | B65: Marketing & Sales | C65: Campaign manager | D65: fixedUsd | E65: 1500 | F65: Fixed monthly USD amount.
A66: ms.content | B66: Marketing & Sales | C66: Content creation | D66: fixedUsd | E66: 1500 | F66: Fixed monthly USD amount.
A67: ms.tripleBundle | B67: Marketing & Sales | C67: Triple Bundle equipment | D67: calculatedTripleBundle | E67: 70 | F67: Unit cost multiplied by New Subscribers.
A68: ops.support | B68: Operations | C68: Customer support - Yaar | D68: fixedUsd | E68: 4000 | F68: Fixed monthly USD amount.
A69: ops.installations | B69: Operations | C69: Online installation manager | D69: fixedUsd | E69: 3333 | F69: Fixed monthly USD amount.
A70: mgmt.ceo | B70: Management | C70: CEO - Maor | D70: fixedUsd | E70: 5000 | F70: Fixed monthly USD amount.
...

Sheet Forecast
A1: SPECTRA | 36-Month Financial Forecast
A2: Forecast Period | B2: 36-month model | C2: Year 1 | O2: Year 2 | AA2: Year 3 | AM2: Total / Ending
A3: Category | B3: Row | C3: Jun 26 | D3: Jul 26 | E3: Aug 26 | F3: Sep 26 | G3: Oct 26 | H3: Nov 26 | I3: Dec 26 | J3: Jan 27 | K3: Feb 27 | L3: Mar 27 | M3: Apr 27 | N3: May 27 | O3: Jun 27 | P3: Jul 27 | Q3: Aug 27 | R3: Sep 27 | S3: Oct 27 | T3: Nov 27 | U3: Dec 27 | V3: Jan 28 | W3: Feb 28 | X3: Mar 28 | Y3: Apr 28 | Z3: May 28 | AA3: Jun 28 | AB3: Jul 28 | AC3: Aug 28 | AD3: Sep 28 | AE3: Oct 28 | AF3: Nov 28 | AG3: Dec 28 | AH3: Jan 29 | AI3: Feb 29 | AJ3: Mar 29 | AK3: Apr 29 | AL3: May 29 | AM3: Total / Ending
A4: Subscribers | B4: Subscribers Start | C4: ='Assumptions'!B8 | D4: =C7 | E4: =D7 | F4: =E7 | G4: =F7 | H4: =G7 | I4: =H7 | J4: =I7 | K4: =J7 | ... AL4: =AK7 | AM4: =AL4
A5: Subscribers | B5: New Subscribers | C5: =C19/C8 | D5: =D19/D8 | E5: =E19/E8 | F5: =F19/F8 | G5: =G19/G8 | H5: =H19/H8 | I5: =I19/I8 | J5: =J19/J8 | ... AL5: =AL19/AL8 | AM5: =SUM(C5:AL5)
A6: Subscribers | B6: Churned Subscribers | C6: =C4*C10 | D6: =D4*D10 | E6: =E4*E10 | F6: =F4*F10 | G6: =G4*G10 | H6: =H4*H10 | I6: =I4*I10 | J6: =J4*J10 | ... AL6: =AL4*AL10 | AM6: =SUM(C6:AL6)
A7: Subscribers | B7: Subscribers End | C7: =C4+C5-C6 | D7: =D4+D5-D6 | E7: =E4+E5-E6 | F7: =F4+F5-F6 | G7: =G4+G5-G6 | H7: =H4+H5-H6 | I7: =I4+I5-I6 | J7: =J4+J5-J6 | ... AL7: =AL4+AL5-AL6 | AM7: =AL7
A8: Growth Assumptions | B8: CAC | C8: ='Assumptions'!B20 | D8: ='Assumptions'!B21 | E8: ='Assumptions'!B22 | F8: ='Assumptions'!B23 | G8: ='Assumptions'!B24 | H8: ='Assumptions'!B25 | I8: ='Assumptions'!B26 | J8: ='Assumptions'!B27 | K8: ='Assumptions'!B28 | L8: ='Assumptions'!B29 | M8: ='Assumptions'!B30 | N8: ='Assumptions'!B31 | O8: ='Assumptions'!B32 | P8: ='Assumptions'!B33 | Q8: ='Assumptions'!B34 | R8: ='Assumptions'!B35 | S8: ='Assumptions'!B36 | T8: ='Assumptions'!B37 | U8: ='Assumptions'!B38 | V8: ='Assumptions'!B39 | W8: ='Assumptions'!B40 | X8: ='Assumptions'!B41 | Y8: ='Assumptions'!B42 | Z8: ='Assumptions'!B43 | AA8: ='Assumptions'!B44 | AB8: ='Assumptions'!B45 | AC8: ='Assumptions'!B46 | AD8: ='Assumptions'!B47 | AE8: ='Assumptions'!B48 | AF8: ='Assumptions'!B49 | AG8: ='Assumptions'!B50 | AH8: ='Assumptions'!B51 | AI8: ='Assumptions'!B52 | AJ8: ='Assumptions'!B53 | AK8: ='Assumptions'!B54 | AL8: ='Assumptions'!B55 | AM8: =AL8
A9: Growth Assumptions | B9: ARPU | C9: ='Assumptions'!C20 | D9: ='Assumptions'!C21 | E9: ='Assumptions'!C22 | F9: ='Assumptions'!C23 | G9: ='Assumptions'!C24 | H9: ='Assumptions'!C25 | I9: ='Assumptions'!C26 | J9: ='Assumptions'!C27 | K9: ='Assumptions'!C28 | L9: ='Assumptions'!C29 | M9: ='Assumptions'!C30 | N9: ='Assumptions'!C31 | O9: ='Assumptions'!C32 | P9: ='Assumptions'!C33 | Q9: ='Assumptions'!C34 | R9: ='Assumptions'!C35 | S9: ='Assumptions'!C36 | T9: ='Assumptions'!C37 | U9: ='Assumptions'!C38 | V9: ='Assumptions'!C39 | W9: ='Assumptions'!C40 | X9: ='Assumptions'!C41 | Y9: ='Assumptions'!C42 | Z9: ='Assumptions'!C43 | AA9: ='Assumptions'!C44 | AB9: ='Assumptions'!C45 | AC9: ='Assumptions'!C46 | AD9: ='Assumptions'!C47 | AE9: ='Assumptions'!C48 | AF9: ='Assumptions'!C49 | AG9: ='Assumptions'!C50 | AH9: ='Assumptions'!C51 | AI9: ='Assumptions'!C52 | AJ9: ='Assumptions'!C53 | AK9: ='Assumptions'!C54 | AL9: ='Assumptions'!C55 | AM9: =AL9
A10: Growth Assumptions | B10: Churn % | C10: ='Assumptions'!D20 | D10: ='Assumptions'!D21 | E10: ='Assumptions'!D22 | F10: ='Assumptions'!D23 | G10: ='Assumptions'!D24 | H10: ='Assumptions'!D25 | I10: ='Assumptions'!D26 | J10: ='Assumptions'!D27 | K10: ='Assumptions'!D28 | L10: ='Assumptions'!D29 | M10: ='Assumptions'!D30 | N10: ='Assumptions'!D31 | O10: ='Assumptions'!D32 | P10: ='Assumptions'!D33 | Q10: ='Assumptions'!D34 | R10: ='Assumptions'!D35 | S10: ='Assumptions'!D36 | T10: ='Assumptions'!D37 | U10: ='Assumptions'!D38 | V10: ='Assumptions'!D39 | W10: ='Assumptions'!D40 | X10: ='Assumptions'!D41 | Y10: ='Assumptions'!D42 | Z10: ='Assumptions'!D43 | AA10: ='Assumptions'!D44 | AB10: ='Assumptions'!D45 | AC10: ='Assumptions'!D46 | AD10: ='Assumptions'!D47 | AE10: ='Assumptions'!D48 | AF10: ='Assumptions'!D49 | AG10: ='Assumptions'!D50 | AH10: ='Assumptions'!D51 | AI10: ='Assumptions'!D52 | AJ10: ='Assumptions'!D53 | AK10: ='Assumptions'!D54 | AL10: ='Assumptions'!D55 | AM10: =AL10
A11: Revenue | B11: MRR | C11: =C7*C9 | D11: =D7*D9 | E11: =E7*E9 | F11: =F7*F9 | G11: =G7*G9 | H11: =H7*H9 | I11: =I7*I9 | J11: =J7*J9 | ... AL11: =AL7*AL9 | AM11: =AL13
A12: Revenue | B12: ARR | C12: =C11*12 | D12: =D11*12 | E12: =E11*12 | F12: =F11*12 | G12: =G11*12 | H12: =H11*12 | I12: =I11*12 | J12: =J11*12 | ... AL12: =AL11*12 | AM12: =AL14
A13: Research & Development | B13: Expense category
A14: Research & Development | B14: Achela developer | C14: ='Assumptions'!C82 | D14: ='Assumptions'!D82 | E14: ='Assumptions'!E82 | F14: ='Assumptions'!F82 | G14: ='Assumptions'!G82 | H14: ='Assumptions'!H82 | I14: ='Assumptions'!I82 | J14: ='Assumptions'!J82 | ... AL14: ='Assumptions'!AL82 | AM14: =SUM(C16:AL16)
A15: Research & Development | B15: IT / servers | C15: ='Assumptions'!C83 | D15: ='Assumptions'!D83 | E15: ='Assumptions'!E83 | F15: ='Assumptions'!F83 | G15: ='Assumptions'!G83 | H15: ='Assumptions'!H83 | I15: ='Assumptions'!I83 | J15: ='Assumptions'!J83 | ... AL15: ='Assumptions'!AL83 | AM15: =SUM(C17:AL17)
A16: Research & Development | B16: AI tools | C16: ='Assumptions'!C84 | D16: ='Assumptions'!D84 | E16: ='Assumptions'!E84 | F16: ='Assumptions'!F84 | G16: ='Assumptions'!G84 | H16: ='Assumptions'!H84 | I16: ='Assumptions'!I84 | J16: ='Assumptions'!J84 | ... AL16: ='Assumptions'!AL84 | AM16: =SUM(C18:AL18)
A17: Marketing & Sales | B17: Expense category
A18: Marketing & Sales | B18: Campaigns | C18: ='Assumptions'!C85 | D18: ='Assumptions'!D85 | E18: ='Assumptions'!E85 | F18: ='Assumptions'!F85 | G18: ='Assumptions'!G85 | H18: ='Assumptions'!H85 | I18: ='Assumptions'!I85 | J18: ='Assumptions'!J85 | ... AL18: ='Assumptions'!AL85 | AM18: =SUM(C20:AL20)
A19: Marketing & Sales | B19: Marketing Acquisition Spend | C19: =SUM(C18,C20:C21,C23) | D19: =SUM(D18,D20:D21,D23) | E19: =SUM(E18,E20:E21,E23) | F19: =SUM(F18,F20:F21,F23) | G19: =SUM(G18,G20:G21,G23) | H19: =SUM(H18,H20:H21,H23) | I19: =SUM(I18,I20:I21,I23) | J19: =SUM(J18,J20:J21,J23) | ... AL19: =SUM(AL18,AL20:AL21,AL23)
A20: Marketing & Sales | B20: Campaign manager | C20: ='Assumptions'!C86 | D20: ='Assumptions'!D86 | E20: ='Assumptions'!E86 | F20: ='Assumptions'!F86 | G20: ='Assumptions'!G86 | H20: ='Assumptions'!H86 | I20: ='Assumptions'!I86 | J20: ='Assumptions'!J86 | ... AL20: ='Assumptions'!AL86 | AM20: =SUM(C21:AL21)
A21: Marketing & Sales | B21: Content creation | C21: ='Assumptions'!C87 | D21: ='Assumptions'!D87 | E21: ='Assumptions'!E87 | F21: ='Assumptions'!F87 | G21: ='Assumptions'!G87 | H21: ='Assumptions'!H87 | I21: ='Assumptions'!I87 | J21: ='Assumptions'!J87 | ... AL21: ='Assumptions'!AL87 | AM21: =SUM(C22:AL22)
A22: Marketing & Sales | B22: Triple Bundle equipment | C22: =C5*'Assumptions'!C88 | D22: =D5*'Assumptions'!D88 | E22: =E5*'Assumptions'!E88 | F22: =F5*'Assumptions'!F88 | G22: =G5*'Assumptions'!G88 | H22: =H5*'Assumptions'!H88 | I22: =I5*'Assumptions'!I88 | J22: =J5*'Assumptions'!J88 | ... AL22: =AL5*'Assumptions'!AL88 | AM22: =SUM(C23:AL23)
A23: Marketing & Sales | B23: Leades Manager | C23: ='Assumptions'!C97 | D23: ='Assumptions'!D97 | E23: ='Assumptions'!E97 | F23: ='Assumptions'!F97 | G23: ='Assumptions'!G97 | H23: ='Assumptions'!H97 | I23: ='Assumptions'!I97 | J23: ='Assumptions'!J97 | ... AL23: ='Assumptions'!AL97 | AM23: =SUM(C24:AL24)
A24: Operations | B24: Expense category
A25: Operations | B25: Customer support - Yaar | C25: ='Assumptions'!C89 | D25: ='Assumptions'!D89 | E25: ='Assumptions'!E89 | F25: ='Assumptions'!F89 | G25: ='Assumptions'!G89 | H25: ='Assumptions'!H89 | I25: ='Assumptions'!I89 | J25: ='Assumptions'!J89 | ... AL25: ='Assumptions'!AL89 | AM25: =SUM(C26:AL26)
A26: Operations | B26: Online installation manager | C26: ='Assumptions'!C90 | D26: ='Assumptions'!D90 | E26: ='Assumptions'!E90 | F26: ='Assumptions'!F90 | G26: ='Assumptions'!G90 | H26: ='Assumptions'!H90 | I26: ='Assumptions'!I90 | J26: ='Assumptions'!J90 | ... AL26: ='Assumptions'!AL90 | AM26: =SUM(C27:AL27)
A27: Operations | B27: Costumer Sucsess | C27: ='Assumptions'!C96 | D27: ='Assumptions'!D96 | E27: ='Assumptions'!E96 | F27: ='Assumptions'!F96 | G27: ='Assumptions'!G96 | H27: ='Assumptions'!H96 | I27: ='Assumptions'!I96 | J27: ='Assumptions'!J96 | ... AL27: ='Assumptions'!AL96 | AM27: =SUM(C28:AL28)
A28: Management | B28: Expense category
A29: Management | B29: CEO - Maor | C29: ='Assumptions'!C91 | D29: ='Assumptions'!D91 | E29: ='Assumptions'!E91 | F29: ='Assumptions'!F91 | G29: ='Assumptions'!G91 | H29: ='Assumptions'!H91 | I29: ='Assumptions'!I91 | J29: ='Assumptions'!J91 | ... AL29: ='Assumptions'!AL91 | AM29: =SUM(C30:AL30)
A30: Management | B30: COO - Elad | C30: ='Assumptions'!C92 | D30: ='Assumptions'!D92 | E30: ='Assumptions'!E92 | F30: ='Assumptions'!F92 | G30: ='Assumptions'!G92 | H30: ='Assumptions'!H92 | I30: ='Assumptions'!I92 | J30: ='Assumptions'!J92 | ... AL30: ='Assumptions'!AL92 | AM30: =SUM(C31:AL31)
A31: Accounting / Admin | B31: Expense category
A32: Accounting / Admin | B32: Bookkeeping | C32: ='Assumptions'!C93 | D32: ='Assumptions'!D93 | E32: ='Assumptions'!E93 | F32: ='Assumptions'!F93 | G32: ='Assumptions'!G93 | H32: ='Assumptions'!H93 | I32: ='Assumptions'!I93 | J32: ='Assumptions'!J93 | ... AL32: ='Assumptions'!AL93 | AM32: =SUM(C33:AL33)
A33: Accounting / Admin | B33: VAT Israel | C33: ='Assumptions'!B11*C9*'Assumptions'!C94 | D33: ='Assumptions'!B11*D9*'Assumptions'!D94 | E33: ='Assumptions'!B11*E9*'Assumptions'!E94 | F33: ='Assumptions'!B11*F9*'Assumptions'!F94 | G33: ='Assumptions'!B11*G9*'Assumptions'!G94 | H33: ='Assumptions'!B11*H9*'Assumptions'!H94 | I33: ='Assumptions'!B11*I9*'Assumptions'!I94 | J33: ='Assumptions'!B11*J9*'Assumptions'!J94 | K33: ='Assumptions'!B11*K9*'Assumptions'!K94 | L33: ='Assumptions'!B11*L9*'Assumptions'!L94 | M33: ='Assumptions'!B11*M9*'Assumptions'!M94 | N33: ='Assumptions'!B11*N9*'Assumptions'!N94 | O33: ='Assumptions'!B11*O9*'Assumptions'!O94 | P33: ='Assumptions'!B11*P9*'Assumptions'!P94 | Q33: ='Assumptions'!B11*Q9*'Assumptions'!Q94 | R33: ='Assumptions'!B11*R9*'Assumptions'!R94 | S33: ='Assumptions'!B11*S9*'Assumptions'!S94 | T33: ='Assumptions'!B11*T9*'Assumptions'!T94 | U33: ='Assumptions'!B11*U9*'Assumptions'!U94 | V33: ='Assumptions'!B11*V9*'Assumptions'!V94 | W33: ='Assumptions'!B11*W9*'Assumptions'!W94 | X33: ='Assumptions'!B11*X9*'Assumptions'!X94 | Y33: ='Assumptions'!B11*Y9*'Assumptions'!Y94 | Z33: ='Assumptions'!B11*Z9*'Assumptions'!Z94 | AA33: ='Assumptions'!B11*AA9*'Assumptions'!AA94 | AB33: ='Assumptions'!B11*AB9*'Assumptions'!AB94 | AC33: ='Assumptions'!B11*AC9*'Assumptions'!AC94 | AD33: ='Assumptions'!B11*AD9*'Assumptions'!AD94 | AE33: ='Assumptions'!B11*AE9*'Assumptions'!AE94 | AF33: ='Assumptions'!B11*AF9*'Assumptions'!AF94 | AG33: ='Assumptions'!B11*AG9*'Assumptions'!AG94 | AH33: ='Assumptions'!B11*AH9*'Assumptions'!AH94 | AI33: ='Assumptions'!B11*AI9*'Assumptions'!AI94 | AJ33: ='Assumptions'!B11*AJ9*'Assumptions'!AJ94 | AK33: ='Assumptions'!B11*AK9*'Assumptions'!AK94 | AL33: ='Assumptions'!B11*AL9*'Assumptions'!AL94 | AM33: =SUM(C34:AL34)
A34: Accounting / Admin | B34: Miscellaneous / equipment | C34: ='Assumptions'!C95 | D34: ='Assumptions'!D95 | E34: ='Assumptions'!E95 | F34: ='Assumptions'!F95 | G34: ='Assumptions'!G95 | H34: ='Assumptions'!H95 | I34: ='Assumptions'!I95 | J34: ='Assumptions'!J95 | ... AL34: ='Assumptions'!AL95 | AM34: =SUM(C35:AL35)
A35: Expenses | B35: Total Expenses | C35: =SUM(C14:C16,C18,C20:C23,C25:C27,C29:C30,C32:C34) | D35: =SUM(D14:D16,D18,D20:D23,D25:D27,D29:D30,D32:D34) | E35: =SUM(E14:E16,E18,E20:E23,E25:E27,E29:E30,E32:E34) | F35: =SUM(F14:F16,F18,F20:F23,F25:F27,F29:F30,F32:F34) | G35: =SUM(G14:G16,G18,G20:G23,G25:G27,G29:G30,G32:G34) | H35: =SUM(H14:H16,H18,H20:H23,H25:H27,H29:H30,H32:H34) | I35: =SUM(I14:I16,I18,I20:I23,I25:I27,I29:I30,I32:I34) | J35: =SUM(J14:J16,J18,J20:J23,J25:J27,J29:J30,J32:J34) | ... AL35: =SUM(AL14:AL16,AL18,AL20:AL23,AL25:AL27,AL29:AL30,AL32:AL34) | AM35: =SUM(C36:AL36)
A36: Profit | B36: EBITDA / Profit | C36: =C11-C35 | D36: =D11-D35 | E36: =E11-E35 | F36: =F11-F35 | G36: =G11-G35 | H36: =H11-H35 | I36: =I11-I35 | J36: =J11-J35 | ... AL36: =AL11-AL35 | AM36: =SUM(C37:AL37)
A37: Profit | B37: Cumulative EBITDA | C37: =C36 | D37: =C37+D36 | E37: =D37+E36 | F37: =E37+F36 | G37: =F37+G36 | H37: =G37+H36 | I37: =H37+I36 | J37: =I37+J36 | K37: =J37+K36 | ... AL37: =AK37+AL36 | AM37: =AL38
A38: Cash | B38: Peak Cash Need | C38: =ABS(MIN(0,C37)) | D38: =ABS(MIN(0,D37)) | E38: =ABS(MIN(0,E37)) | F38: =ABS(MIN(0,F37)) | G38: =ABS(MIN(0,G37)) | H38: =ABS(MIN(0,H37)) | I38: =ABS(MIN(0,I37)) | J38: =ABS(MIN(0,J37)) | ... AL38: =ABS(MIN(0,AL37)) | AM38: =AL39
